Workbook

Sheet Invest. IF
A1: ID | B1: Comuna | C1: N° regional Incendio | D1: Nombre incendio | E1: Código causa Investigada | F1: Nombre causa específica | G1: Codigo causa general | H1: Causa General | I1: Grupo de causas | J1: X | K1: Y | L1: Sup | M1: Mes investigación | N1: Nombre informe | O1: Provincia | P1: INICIO INCENDIO | Q1: MES1 | R1: MES2
A2: 1 | B2: San Clemente | C2: 5 | D2: Flor del Llano | E2: 4.8.1 | F2: =IF(E2="","",VLOOKUP(E2,Causas!$A$2:$B$90,2,FALSE)) -> Quema no avisada con fines de limpieza en canales, cunetas, cercos o caminos (en predios particulares o públicos) que se propaga libre y sin control | G2: =IF(E2="","",VLOOKUP(E2,Causas!$A$2:$D$90,3,FALSE())) -> 4.8 | H2: =IF(E2="","",VLOOKUP(E2,Causas!$A$2:$D$90,4,FALSE())) -> Otras quemas | I2: =IF(E2="","",VLOOKUP(E2,Causas!$A$2:$E$90,5,FALSE())) -> Negligentes | J2: 269761 | K2: 6068526 | L2: 1.7 | M2: Septiembre | N2: ITA_N-1_R20-FLOR DEL LLANO_NR-5 | O2: Talca | P2: 45916 | Q2: =MONTH(P2) -> 9 | R2: Septiembre
A3: 2 | B3: Pelluhue | C3: 6 | D3: Canelillos | E3: 4.1.1 | F3: =IF(E3="","",VLOOKUP(E3,Causas!$A$2:$B$90,2,FALSE)) -> Quema no avisada de desechos forestales que se propaga libre y sin control | G3: =IF(E3="","",VLOOKUP(E3,Causas!$A$2:$D$90,3,FALSE())) -> 4.1 | H3: =IF(E3="","",VLOOKUP(E3,Causas!$A$2:$D$90,4,FALSE())) -> Faenas forestales | I3: =IF(E3="","",VLOOKUP(E3,Causas!$A$2:$E$90,5,FALSE())) -> Negligentes | J3: 710893 | K3: 6015439 | L3: 0.6 | M3: Septiembre | N3: ITA_N-2_R20-CANELILLOS_NR-6 | O3: Cauquenes | P3: 45924 | Q3: =MONTH(P3) -> 9 | R3: Septiembre
A4: 3 | B4: Parral | C4: 7 | D4: San Pablo | E4: 4.2.1 | F4: =IF(E4="","",VLOOKUP(E4,Causas!$A$2:$B$90,2,FALSE)) -> Quema no avisada de desechos agrícolas que se propaga libre y sin control | G4: =IF(E4="","",VLOOKUP(E4,Causas!$A$2:$D$90,3,FALSE())) -> 4.2 | H4: =IF(E4="","",VLOOKUP(E4,Causas!$A$2:$D$90,4,FALSE())) -> Faenas agrícolas y pecuarias | I4: =IF(E4="","",VLOOKUP(E4,Causas!$A$2:$E$90,5,FALSE())) -> Negligentes | J4: 248592 | K4: 5994895 | L4: 0.6 | M4: Septiembre | N4: ITA_N-3_R20-SAN PABLO_NR-7 | O4: Linares | P4: 45925 | Q4: =MONTH(P4) -> 9 | R4: Septiembre
A5: 4 | B5: Pencahue | C5: 9 | D5: Santa Patricia | E5: 4.6.5 | F5: =IF(E5="","",VLOOKUP(E5,Causas!$A$2:$B$90,2,FALSE)) -> Empleo de fuentes de calor en actividades relacionadas a parcelaciones (asados, tijerales, fogatas, otros) | G5: =IF(E5="","",VLOOKUP(E5,Causas!$A$2:$D$90,3,FALSE())) -> 4.6 | H5: =IF(E5="","",VLOOKUP(E5,Causas!$A$2:$D$90,4,FALSE())) -> Parcelaciones, edificaciones residenciales, industriales u otras en zonas rurales o de interfaz | I5: =IF(E5="","",VLOOKUP(E5,Causas!$A$2:$E$90,5,FALSE())) -> Negligentes | J5: 255515 | K5: 6084357 | L5: 0.8 | M5: Octubre | N5: ITA_N-4_R20-SANTA PATRICIA_NR-9 | O5: Talca | P5: 45929 | Q5: =MONTH(P5) -> 9 | R5: Septiembre
A6: 5 | B6: Talca | C6: 11 | D6: Palmira | E6: 4.8.1 | F6: =IF(E6="","",VLOOKUP(E6,Causas!$A$2:$B$90,2,FALSE)) -> Quema no avisada con fines de limpieza en canales, cunetas, cercos o caminos (en predios particulares o públicos) que se propaga libre y sin control | G6: =IF(E6="","",VLOOKUP(E6,Causas!$A$2:$D$90,3,FALSE())) -> 4.8 | H6: =IF(E6="","",VLOOKUP(E6,Causas!$A$2:$D$90,4,FALSE())) -> Otras quemas | I6: =IF(E6="","",VLOOKUP(E6,Causas!$A$2:$E$90,5,FALSE())) -> Negligentes | J6: 261374 | K6: 6072852 | L6: 0.5 | M6: Octubre | N6: ITA_N-5_R20-PALMIRA_NR-11 | O6: Talca | P6: 45930 | Q6: =MONTH(P6) -> 9 | R6: Septiembre
A7: 6 | B7: Teno | C7: 14 | D7: Rincón de San Carlos | E7: 4.2.8 | F7: =IF(E7="","",VLOOKUP(E7,Causas!$A$2:$B$90,2,FALSE)) -> Otras causas negligentes no clasificadas en faenas agrícolas y pecuarias | G7: =IF(E7="","",VLOOKUP(E7,Causas!$A$2:$D$90,3,FALSE())) -> 4.2 | H7: =IF(E7="","",VLOOKUP(E7,Causas!$A$2:$D$90,4,FALSE())) -> Faenas agrícolas y pecuarias | I7: =IF(E7="","",VLOOKUP(E7,Causas!$A$2:$E$90,5,FALSE())) -> Negligentes | J7: 317177 | K7: 6137223 | L7: 0.5 | M7: Octubre | N7: ITA_N-6_R20-RINCON DE SAN CARLOS_NR-14 | O7: Curicó | P7: 45947 | Q7: =MONTH(P7) -> 10
A8: 7 | B8: Sagrada Familia | C8: 19 | D8: La Isla | E8: 4.2.1 | F8: =IF(E8="","",VLOOKUP(E8,Causas!$A$2:$B$90,2,FALSE)) -> Quema no avisada de desechos agrícolas que se propaga libre y sin control | G8: =IF(E8="","",VLOOKUP(E8,Causas!$A$2:$D$90,3,FALSE())) -> 4.2 | H8: =IF(E8="","",VLOOKUP(E8,Causas!$A$2:$D$90,4,FALSE())) -> Faenas agrícolas y pecuarias | I8: =IF(E8="","",VLOOKUP(E8,Causas!$A$2:$E$90,5,FALSE())) -> Negligentes | J8: 258197 | K8: 6111756 | L8: 1.75 | M8: Octubre | N8: ITA_N-7_R20-LA ISLA_NR-19 | O8: Curicó | P8: 45950 | Q8: =MONTH(P8) -> 10
A9: 8 | B9: Sagrada Familia | C9: 20 | D9: Huaquen | E9: 4.8.4 | F9: =IF(E9="","",VLOOKUP(E9,Causas!$A$2:$B$90,2,FALSE)) -> Empleo de fuentes de calor para eliminación de fauna (roedores, reptiles, avispas, otros) | G9: =IF(E9="","",VLOOKUP(E9,Causas!$A$2:$D$90,3,FALSE())) -> 4.8 | H9: =IF(E9="","",VLOOKUP(E9,Causas!$A$2:$D$90,4,FALSE())) -> Otras quemas | I9: =IF(E9="","",VLOOKUP(E9,Causas!$A$2:$E$90,5,FALSE())) -> Negligentes | J9: 256366 | K9: 6111056 | L9: 0.3 | M9: Octubre | N9: ITA_N-8_R20-HUAQUEN_NR-20 | O9: Curicó | P9: 45950 | Q9: =MONTH(P9) -> 10
A10: 9 | B10: Cauquenes | C10: 23 | D10: Tabolguen | E10: 2.1.1 | F10: =IF(E10="","",VLOOKUP(E10,Causas!$A$2:$B$90,2,FALSE)) -> Provocado, no se identifica la motivación | G10: =IF(E10="","",VLOOKUP(E10,Causas!$A$2:$D$90,3,FALSE())) -> 2.1 | H10: =IF(E10="","",VLOOKUP(E10,Causas!$A$2:$D$90,4,FALSE())) -> Incendios intencionales | I10: =IF(E10="","",VLOOKUP(E10,Causas!$A$2:$E$90,5,FALSE())) -> Intencionales | J10: 736662 | K10: 6022384 | L10: 1.1 | M10: Octubre | N10: ITA_N-9_R20-TABOLGUEN_NR-23 | O10: Cauquenes | P10: 45952 | Q10: =MONTH(P10) -> 10
A11: 10 | B11: Pelluhue | C11: 21 | D11: Chovellen | E11: 4.10.12 | F11: =IF(E11="","",VLOOKUP(E11,Causas!$A$2:$B$90,2,FALSE)) -> Otras actividades negligentes no clasificadas | G11: =IF(E11="","",VLOOKUP(E11,Causas!$A$2:$D$90,3,FALSE())) -> 4.10 | H11: =IF(E11="","",VLOOKUP(E11,Causas!$A$2:$D$90,4,FALSE())) -> Otras causas | I11: =IF(E11="","",VLOOKUP(E11,Causas!$A$2:$E$90,5,FALSE())) -> Negligentes | J11: 711105 | K11: 6024701 | L11: 1 | M11: Octubre | N11: ITA_N-10_R20-CHOVELLEN_NR-21 | O11: Cauquenes | P11: 45951 | Q11: =MONTH(P11) -> 10
A12: 11 | B12: Yerbas Buenas | C12: 33 | D12: Coironal | E12: 4.2.6 | F12: =IF(E12="","",VLOOKUP(E12,Causas!$A$2:$B$90,2,FALSE)) -> Quema avisada de desechos agrícolas mal ejecutada que se propaga libre y sin control (según plan de quema y/o aviso de quemas) | G12: =IF(E12="","",VLOOKUP(E12,Causas!$A$2:$D$90,3,FALSE())) -> 4.2 | H12: =IF(E12="","",VLOOKUP(E12,Causas!$A$2:$D$90,4,FALSE())) -> Faenas agrícolas y pecuarias | I12: =IF(E12="","",VLOOKUP(E12,Causas!$A$2:$E$90,5,FALSE())) -> Negligentes | J12: 260770 | K12: 6038159 | L12: 0.5 | M12: Octubre | N12: ITA_N-11_R20-COIRONAL_NR-33 | O12: Linares | P12: 45956 | Q12: =MONTH(P12) -> 10
A13: 12 | B13: Longaví | C13: 37 | D13: Camino a la quinta | E13: 4.2.8 | F13: =IF(E13="","",VLOOKUP(E13,Causas!$A$2:$B$90,2,FALSE)) -> Otras causas negligentes no clasificadas en faenas agrícolas y pecuarias | G13: =IF(E13="","",VLOOKUP(E13,Causas!$A$2:$D$90,3,FALSE())) -> 4.2 | H13: =IF(E13="","",VLOOKUP(E13,Causas!$A$2:$D$90,4,FALSE())) -> Faenas agrícolas y pecuarias | I13: =IF(E13="","",VLOOKUP(E13,Causas!$A$2:$E$90,5,FALSE())) -> Negligentes | J13: 259646 | K13: 6003027 | L13: 0.2 | M13: Octubre | N13: ITA_N-12_R20-CAMINO A LA QUINTA_NR-37 | O13: Linares | P13: 45958 | Q13: =MONTH(P13) -> 10
A14: 13 | B14: Romeral | C14: 28 | D14: Guiaco 3 | E14: 4.2.8 | F14: =IF(E14="","",VLOOKUP(E14,Causas!$A$2:$B$90,2,FALSE)) -> Otras causas negligentes no clasificadas en faenas agrícolas y pecuarias | G14: =IF(E14="","",VLOOKUP(E14,Causas!$A$2:$D$90,3,FALSE())) -> 4.2 | H14: =IF(E14="","",VLOOKUP(E14,Causas!$A$2:$D$90,4,FALSE())) -> Faenas agrícolas y pecuarias | I14: =IF(E14="","",VLOOKUP(E14,Causas!$A$2:$E$90,5,FALSE())) -> Negligentes | J14: 317629 | K14: 6129030 | L14: 0.03 | M14: Octubre | N14: ITA_N-13_R20-GUAICO 3_NR-28 | O14: Curicó | P14: 45954 | Q14: =MONTH(P14) -> 10
A15: 14 | B15: Romeral | C15: 42 | D15: Tres Esquinas | E15: 4.2.8 | F15: =IF(E15="","",VLOOKUP(E15,Causas!$A$2:$B$90,2,FALSE)) -> Otras causas negligentes no clasificadas en faenas agrícolas y pecuarias | G15: =IF(E15="","",VLOOKUP(E15,Causas!$A$2:$D$90,3,FALSE())) -> 4.2 | H15: =IF(E15="","",VLOOKUP(E15,Causas!$A$2:$D$90,4,FALSE())) -> Faenas agrícolas y pecuarias | I15: =IF(E15="","",VLOOKUP(E15,Causas!$A$2:$E$90,5,FALSE())) -> Negligentes | J15: 308416 | K15: 6128439 | L15: 0.47 | M15: Octubre | N15: ITA_N-14_R20-TRES ESQUINAS_NR-42 | O15: Curicó | P15: 45959 | Q15: =MONTH(P15) -> 10
A16: 15 | B16: Molina | C16: 34 | D16: Callejón San Luis | E16: 4.6.5 | F16: =IF(E16="","",VLOOKUP(E16,Causas!$A$2:$B$90,2,FALSE)) -> Empleo de fuentes de calor en actividades relacionadas a parcelaciones (asados, tijerales, fogatas, otros) | G16: =IF(E16="","",VLOOKUP(E16,Causas!$A$2:$D$90,3,FALSE())) -> 4.6 | H16: =IF(E16="","",VLOOKUP(E16,Causas!$A$2:$D$90,4,FALSE())) -> Parcelaciones, edificaciones residenciales, industriales u otras en zonas rurales o de interfaz | I16: =IF(E16="","",VLOOKUP(E16,Causas!$A$2:$E$90,5,FALSE())) -> Negligentes | J16: 294000 | K16: 6107904 | L16: 0.2 | M16: Noviembre | N16: ITA_N-15_R20-CALLEJÓN SAN LUIS_NR-34 | O16: Curicó | P16: 45956 | Q16: =MONTH(P16) -> 10
A17: 16 | B17: Molina | C17: 44 | D17: Santa Teresa | E17: 4.2.8 | F17: =IF(E17="","",VLOOKUP(E17,Causas!$A$2:$B$90,2,FALSE)) -> Otras causas negligentes no clasificadas en faenas agrícolas y pecuarias | G17: =IF(E17="","",VLOOKUP(E17,Causas!$A$2:$D$90,3,FALSE())) -> 4.2 | H17: =IF(E17="","",VLOOKUP(E17,Causas!$A$2:$D$90,4,FALSE())) -> Faenas agrícolas y pecuarias | I17: =IF(E17="","",VLOOKUP(E17,Causas!$A$2:$E$90,5,FALSE())) -> Negligentes | J17: 283407 | K17: 6107447 | L17: 0.5 | M17: Noviembre | N17: ITA_N-16_R20-SANTA TERESA_NR-44 | O17: Curicó | P17: 45960 | Q17: =MONTH(P17) -> 10
A18: 17 | B18: San Rafael | C18: 45 | D18: Los Maquis | E18: 2.1.1 | F18: =IF(E18="","",VLOOKUP(E18,Causas!$A$2:$B$90,2,FALSE)) -> Provocado, no se identifica la motivación | G18: =IF(E18="","",VLOOKUP(E18,Causas!$A$2:$D$90,3,FALSE())) -> 2.1 | H18: =IF(E18="","",VLOOKUP(E18,Causas!$A$2:$D$90,4,FALSE())) -> Incendios intencionales | I18: =IF(E18="","",VLOOKUP(E18,Causas!$A$2:$E$90,5,FALSE())) -> Intencionales | J18: 277237 | K18: 6098686 | L18: 0.2 | M18: Noviembre | N18: ITA_N-17_R20-LOS MAQUIS_NR-45 | O18: Talca | P18: 45960 | Q18: =MONTH(P18) -> 10
... A93: 92 | B93: Maule | C93: 273 | D93: Barros Negros | E93: 5.1.1 | F93: =IF(E93="","",VLOOKUP(E93,Causas!$A$2:$B$90,2,FALSE)) -> Se investiga pero no es posible establecer la causa | G93: =IF(E93="","",VLOOKUP(E93,Causas!$A$2:$D$90,3,FALSE())) -> 5.1 | H93: =IF(E93="","",VLOOKUP(E93,Causas!$A$2:$D$90,4,FALSE())) -> Incendios de causa indeterminada | I93: =IF(E93="","",VLOOKUP(E93,Causas!$A$2:$E$90,5,FALSE())) -> Indeterminadas | J93: 256436 | K93: 6077735 | L93: 3 | M93: Enero | N93: ITA_N-92_R20-BARROS NEGROS_NR-273 | O93: Talca | P93: 46016 | Q93: =MONTH(P93) -> 12
A94: 93 | B94: Cauquenes | C94: 348 | D94: San Pedro | E94: 4.6 | G94: 4.6 | H94: Parcelaciones, edificaciones residenciales, industriales u otras en zonas rurales o de interfaz | I94: Negligentes | J94: 754468 | K94: 6021760 | L94: 433 | M94: Enero | N94: ITA_N-93_R20-SAN PEDRO_NR-348 | O94: Cauquenes | P94: 46033 | Q94: =MONTH(P94) -> 1
A95: 94 | B95: Rauco | C95: 323 | D95: Majadillas | E95: 4.6.5 | F95: =IF(E95="","",VLOOKUP(E95,Causas!$A$2:$B$90,2,FALSE)) -> Empleo de fuentes de calor en actividades relacionadas a parcelaciones (asados, tijerales, fogatas, otros) | G95: =IF(E95="","",VLOOKUP(E95,Causas!$A$2:$D$90,3,FALSE())) -> 4.6 | H95: =IF(E95="","",VLOOKUP(E95,Causas!$A$2:$D$90,4,FALSE())) -> Parcelaciones, edificaciones residenciales, industriales u otras en zonas rurales o de interfaz | I95: =IF(E95="","",VLOOKUP(E95,Causas!$A$2:$E$90,5,FALSE())) -> Negligentes | J95: 271118 | K95: 6122040 | L95: 2.78 | M95: Enero | N95: ITA_N-94_R20-MAJADILLAS_NR-323 | O95: Curicó | P95: 46028 | Q95: =MONTH(P95) -> 1
A96: 95 | B96: Teno | C96: 340 | D96: Rincón de Morales | E96: 1.2.2 | F96: =IF(E96="","",VLOOKUP(E96,Causas!$A$2:$B$90,2,FALSE)) -> Partículas incandescentes generadas por roce de maquinaria o herramienta agrícola con rocas, cercos o material metálico | G96: =IF(E96="","",VLOOKUP(E96,Causas!$A$2:$D$90,3,FALSE())) -> 1.2 | H96: =IF(E96="","",VLOOKUP(E96,Causas!$A$2:$D$90,4,FALSE())) -> Faenas agrícolas y pecuarias | I96: =IF(E96="","",VLOOKUP(E96,Causas!$A$2:$E$90,5,FALSE())) -> Accidentales | J96: 294907 | K96: 6142302 | L96: 10 | M96: Enero | N96: ITA_N-95_R20-RINCÓN DE MORALES_NR-340 | O96: Curicó | P96: 46032 | Q96: =MONTH(P96) -> 1
A97: 96 | B97: Licantén | C97: 306 | D97: Rancura | E97: 4.3.1 | F97: =IF(E97="","",VLOOKUP(E97,Causas!$A$2:$B$90,2,FALSE)) -> Empleo de fuentes de calor en áreas no habilitadas, como fogatas para cocinar, cocinillas, calefacción, elementos para iluminar u otros. | G97: =IF(E97="","",VLOOKUP(E97,Causas!$A$2:$D$90,3,FALSE())) -> 4.3 | H97: =IF(E97="","",VLOOKUP(E97,Causas!$A$2:$D$90,4,FALSE())) -> Actividades al aire libre (camping, excursiones, caza, pesca, otros) | I97: =IF(E97="","",VLOOKUP(E97,Causas!$A$2:$E$90,5,FALSE())) -> Negligentes | J97: 757545 | K97: 6127645 | L97: 5.5 | M97: Enero | N97: ITA_N-96_R20-RANCURA_NR-306 | O97: Curicó | P97: 46023 | Q97: =MONTH(P97) -> 1
A98: 97 | B98: Talca | C98: 371 | D98: Circunvalación norte | E98: 4.6.1 | F98: =IF(E98="","",VLOOKUP(E98,Causas!$A$2:$B$90,2,FALSE)) -> Generado por el uso de equipos o herramientas con fines de construcción, limpieza o montaje de estructuras | G98: =IF(E98="","",VLOOKUP(E98,Causas!$A$2:$D$90,3,FALSE())) -> 4.6 | H98: =IF(E98="","",VLOOKUP(E98,Causas!$A$2:$D$90,4,FALSE())) -> Parcelaciones, edificaciones residenciales, industriales u otras en zonas rurales o de interfaz | I98: =IF(E98="","",VLOOKUP(E98,Causas!$A$2:$E$90,5,FALSE())) -> Negligentes | J98: 257100 | K98: 6078290 | L98: 11 | M98: Enero | N98: ITA_N-97_R20-CIRCUNVALACIÓN NORTE_NR-371 | O98: Talca | P98: 46036 | Q98: =MONTH(P98) -> 1
A99: 98 | B99: Río Claro | C99: 256 | D99: El Álamo | E99: 4.10.12 | F99: =IF(E99="","",VLOOKUP(E99,Causas!$A$2:$B$90,2,FALSE)) -> Otras actividades negligentes no clasificadas | G99: =IF(E99="","",VLOOKUP(E99,Causas!$A$2:$D$90,3,FALSE())) -> 4.10 | H99: =IF(E99="","",VLOOKUP(E99,Causas!$A$2:$D$90,4,FALSE())) -> Otras causas | I99: =IF(E99="","",VLOOKUP(E99,Causas!$A$2:$E$90,5,FALSE())) -> Negligentes | J99: 284975 | K99: 6096774 | L99: 0.8 | M99: Enero | N99: ITA_N-98_R20-EL ALAMO_NR-256 | O99: Talca | P99: 46012 | Q99: =MONTH(P99) -> 12
A100: 99 | B100: Río Claro | C100: 305 | D100: Las Brujas 3 | E100: 4.10.4 | F100: =IF(E100="","",VLOOKUP(E100,Causas!$A$2:$B$90,2,FALSE)) -> Acciones asociadas a fumar | G100: =IF(E100="","",VLOOKUP(E100,Causas!$A$2:$D$90,3,FALSE())) -> 4.10 | H100: =IF(E100="","",VLOOKUP(E100,Causas!$A$2:$D$90,4,FALSE())) -> Otras causas | I100: =IF(E100="","",VLOOKUP(E100,Causas!$A$2:$E$90,5,FALSE())) -> Negligentes | J100: 294168 | K100: 6096026 | L100: 3 | M100: Enero | N100: ITA_N-99_R20-LAS BRUJAS 3_NR-305 | O100: Talca | P100: 46023 | Q100: =MONTH(P100) -> 1
A101: 100 | B101: Pencahue | C101: 327 | D101: Loma Verde | E101: 4.6.1 | F101: =IF(E101="","",VLOOKUP(E101,Causas!$A$2:$B$90,2,FALSE)) -> Generado por el uso de equipos o herramientas con fines de construcción, limpieza o montaje de estructuras | G101: =IF(E101="","",VLOOKUP(E101,Causas!$A$2:$D$90,3,FALSE())) -> 4.6 | H101: =IF(E101="","",VLOOKUP(E101,Causas!$A$2:$D$90,4,FALSE())) -> Parcelaciones, edificaciones residenciales, industriales u otras en zonas rurales o de interfaz | I101: =IF(E101="","",VLOOKUP(E101,Causas!$A$2:$E$90,5,FALSE())) -> Negligentes | J101: 250471 | K101: 6076108 | L101: 0.2 | M101: Enero | N101: ITA_N-100_R20-LOMA VERDE_NR-327 | O101: Talca | P101: 46029 | Q101: =MONTH(P101) -> 1
A102: 101 | B102: Pencahue | C102: 136 | D102: Rauquen | E102: 4.9.4 | F102: =IF(E102="","",VLOOKUP(E102,Causas!$A$2:$B$90,2,FALSE)) -> Sobrecalentamiento de estructuras asociados al sistema eléctrico (poste, transformador, uniones, aisladores, otros) | G102: =IF(E102="","",VLOOKUP(E102,Causas!$A$2:$D$90,3,FALSE())) -> 4.9 | H102: =IF(E102="","",VLOOKUP(E102,Causas!$A$2:$D$90,4,FALSE())) -> Líneas eléctricas | I102: =IF(E102="","",VLOOKUP(E102,Causas!$A$2:$E$90,5,FALSE())) -> Negligentes | J102: 247350 | K102: 6073530 | L102: 0.2 | M102: Enero | N102: ITA_N-101_R20-RAUQUEN_NR-136 | O102: Talca | P102: 45989 | Q102: =MONTH(P102) -> 11
A103: 102 | B103: Maule | C103: 401 | D103: Colín | E103: 4.2.8 | F103: =IF(E103="","",VLOOKUP(E103,Causas!$A$2:$B$90,2,FALSE)) -> Otras causas negligentes no clasificadas en faenas agrícolas y pecuarias | G103: =IF(E103="","",VLOOKUP(E103,Causas!$A$2:$D$90,3,FALSE())) -> 4.2 | H103: =IF(E103="","",VLOOKUP(E103,Causas!$A$2:$D$90,4,FALSE())) -> Faenas agrícolas y pecuarias | I103: =IF(E103="","",VLOOKUP(E103,Causas!$A$2:$E$90,5,FALSE())) -> Negligentes | J103: 248444 | K103: 6070660 | L103: 0.5 | M103: Enero | N103: ITA_N-102_R20-COLÍN_NR-401 | O103: Talca | P103: 46040 | Q103: =MONTH(P103) -> 1
A104: 103 | B104: San Clemente | C104: 405 | D104: Los Largos | E104: 4.2.8 | F104: =IF(E104="","",VLOOKUP(E104,Causas!$A$2:$B$90,2,FALSE)) -> Otras causas negligentes no clasificadas en faenas agrícolas y pecuarias | G104: =IF(E104="","",VLOOKUP(E104,Causas!$A$2:$D$90,3,FALSE())) -> 4.2 | H104: =IF(E104="","",VLOOKUP(E104,Causas!$A$2:$D$90,4,FALSE())) -> Faenas agrícolas y pecuarias | I104: =IF(E104="","",VLOOKUP(E104,Causas!$A$2:$E$90,5,FALSE())) -> Negligentes | J104: 273299 | K104: 6074928 | L104: 1 | M104: Enero | N104: ITA_N-103_R20-LOS LARGOS_NR-405 | O104: Talca | P104: 46041 | Q104: =MONTH(P104) -> 1
A105: 104 | B105: Retiro | C105: 409 | D105: Curacura | E105: 4.2.8 | F105: =IF(E105="","",VLOOKUP(E105,Causas!$A$2:$B$90,2,FALSE)) -> Otras causas negligentes no clasificadas en faenas agrícolas y pecuarias | G105: =IF(E105="","",VLOOKUP(E105,Causas!$A$2:$D$90,3,FALSE())) -> 4.2 | H105: =IF(E105="","",VLOOKUP(E105,Causas!$A$2:$D$90,4,FALSE())) -> Faenas agrícolas y pecuarias | I105: =IF(E105="","",VLOOKUP(E105,Causas!$A$2:$E$90,5,FALSE())) -> Negligentes | J105: 237516 | K105: 6019422 | L105: 42.7 | M105: Enero | N105: ITA_N-104_R20-CURACURA_NR-409 | O105: Linares | P105: 46042 | Q105: =MONTH(P105) -> 1
A106: 105 | B106: Hualañé | C106: 246 | D106: Orilla de Valdés | E106: 4.10.12 | F106: =IF(E106="","",VLOOKUP(E106,Causas!$A$2:$B$90,2,FALSE)) -> Otras actividades negligentes no clasificadas | G106: =IF(E106="","",VLOOKUP(E106,Causas!$A$2:$D$90,3,FALSE())) -> 4.10 | H106: =IF(E106="","",VLOOKUP(E106,Causas!$A$2:$D$90,4,FALSE())) -> Otras causas | I106: =IF(E106="","",VLOOKUP(E106,Causas!$A$2:$E$90,5,FALSE())) -> Negligentes | J106: 260437 | K106: 6115498 | L106: 5 | M106: Enero | N106: ITA_N-105_R20-ORILLA DE VALDES_NR-246 | O106: Curicó | P106: 46010 | Q106: =MONTH(P106) -> 12
... A153: 152 | B153: Talca | C153: 576 | D153: Cruce El Tabaco | E153: 4.8.1 | F153: =IF(E153="","",VLOOKUP(E153,Causas!$A$2:$B$90,2,FALSE)) -> Quema no avisada con fines de limpieza en canales, cunetas, cercos o caminos (en predios particulares o públicos) que se propaga libre y sin control | G153: =IF(E153="","",VLOOKUP(E153,Causas!$A$2:$D$90,3,FALSE())) -> 4.8 | H153: =IF(E153="","",VLOOKUP(E153,Causas!$A$2:$D$90,4,FALSE())) -> Otras quemas | I153: =IF(E153="","",VLOOKUP(E153,Causas!$A$2:$E$90,5,FALSE())) -> Negligentes | J153: 260209 | K153: 6073787 | L153: 2.3 | M153: Febrero | N153: ITA_N-152_R20-CRUCE EL TABACO_NR-576 | O153: Talca | P153: 46080 | Q153: =MONTH(P153) -> 2
A154: 153 | B154: Curepto | C154: 577 | D154: Cruce El Membrillo | E154: 4.6 | G154: 4.6 | H154: Parcelaciones, edificaciones residenciales, industriales u otras en zonas rurales o de interfaz | I154: Negligentes | J154: 230285 | K154: 6111868 | L154: 60 | M154: Marzo | N154: ITA_N-153_R20-CRUCE EL MEMBRILLO_NR-577 | O154: Talca | P154: 46081 | Q154: =MONTH(P154) -> 2
A155: 154 | B155: Pencahue | C155: 418 | D155: Botalcura | E155: 4.6.1 | F155: =IF(E155="","",VLOOKUP(E155,Causas!$A$2:$B$90,2,FALSE)) -> Generado por el uso de equipos o herramientas con fines de construcción, limpieza o montaje de estructuras | G155: =IF(E155="","",VLOOKUP(E155,Causas!$A$2:$D$90,3,FALSE())) -> 4.6 | H155: =IF(E155="","",VLOOKUP(E155,Causas!$A$2:$D$90,4,FALSE())) -> Parcelaciones, edificaciones residenciales, industriales u otras en zonas rurales o de interfaz | I155: =IF(E155="","",VLOOKUP(E155,Causas!$A$2:$E$90,5,FALSE())) -> Negligentes | J155: 246890 | K155: 6091761 | L155: 1.5 | M155: Marzo | N155: ITA_N-154_R20-BOTALCURA_NR-418 | O155: Talca | P155: 46045 | Q155: =MONTH(P155) -> 1
A156: 155 | B156: Talca | C156: 567 | D156: Panguilemo | E156: 4.6.3 | F156: =IF(E156="","",VLOOKUP(E156,Causas!$A$2:$B$90,2,FALSE)) -> Generado por infraestructura destinada a la producción de energía (solar, eólica, otros) | G156: =IF(E156="","",VLOOKUP(E156,Causas!$A$2:$D$90,3,FALSE())) -> 4.6 | H156: =IF(E156="","",VLOOKUP(E156,Causas!$A$2:$D$90,4,FALSE())) -> Parcelaciones, edificaciones residenciales, industriales u otras en zonas rurales o de interfaz | I156: =IF(E156="","",VLOOKUP(E156,Causas!$A$2:$E$90,5,FALSE())) -> Negligentes | J156: 264246 | K156: 6082219 | L156: 1 | M156: Marzo | N156: ITA_N-155_R20-PANGUILEMO_NR-567 | O156: Talca | P156: 46079 | Q156: =MONTH(P156) -> 2
A157: 156 | B157: San Clemente | C157: 436 | D157: Quebrada de agua | E157: 4.2.1 | F157: =IF(E157="","",VLOOKUP(E157,Causas!$A$2:$B$90,2,FALSE)) -> Quema no avisada de desechos agrícolas que se propaga libre y sin control | G157: =IF(E157="","",VLOOKUP(E157,Causas!$A$2:$D$90,3,FALSE())) -> 4.2 | H157: =IF(E157="","",VLOOKUP(E157,Causas!$A$2:$D$90,4,FALSE())) -> Faenas agrícolas y pecuarias | I157: =IF(E157="","",VLOOKUP(E157,Causas!$A$2:$E$90,5,FALSE())) -> Negligentes | J157: 276549 | K157: 6067739 | L157: 5.7 | M157: Marzo | N157: ITA_N-156_R20-QUEBRADA DE AGUA_NR-436 | O157: Talca | P157: 46049 | Q157: =MONTH(P157) -> 1
A158: 157 | B158: Retiro | C158: 346 | D158: El Carmen uno 2 | E158: 2.1.1 | F158: =IF(E158="","",VLOOKUP(E158,Causas!$A$2:$B$90,2,FALSE)) -> Provocado, no se identifica la motivación | G158: =IF(E158="","",VLOOKUP(E158,Causas!$A$2:$D$90,3,FALSE())) -> 2.1 | H158: =IF(E158="","",VLOOKUP(E158,Causas!$A$2:$D$90,4,FALSE())) -> Incendios intencionales | I158: =IF(E158="","",VLOOKUP(E158,Causas!$A$2:$E$90,5,FALSE())) -> Intencionales | J158: 248721 | K158: 6002423 | L158: 0.2 | M158: Marzo | N158: ITA_N-157_R20-EL CARMEN UNO 2_NR-346 | O158: Linares | P158: 46033 | Q158: =MONTH(P158) -> 1
A159: 158 | B159: Retiro | C159: 400 | D159: El Membrillo | E159: 2.1.1 | F159: =IF(E159="","",VLOOKUP(E159,Causas!$A$2:$B$90,2,FALSE)) -> Provocado, no se identifica la motivación | G159: =IF(E159="","",VLOOKUP(E159,Causas!$A$2:$D$90,3,FALSE())) -> 2.1 | H159: =IF(E159="","",VLOOKUP(E159,Causas!$A$2:$D$90,4,FALSE())) -> Incendios intencionales | I159: =IF(E159="","",VLOOKUP(E159,Causas!$A$2:$E$90,5,FALSE())) -> Intencionales | J159: 248779 | K159: 6002349 | L159: 0.2 | M159: Marzo | N159: ITA_N-158_R20-EL MEMBRILLO_NR-400 | O159: Linares | P159: 46040 | Q159: =MONTH(P159) -> 1
A160: 159 | B160: Retiro | C160: 289 | D160: Bajos de Copihue | E160: 2.1.1 | F160: =IF(E160="","",VLOOKUP(E160,Causas!$A$2:$B$90,2,FALSE)) -> Provocado, no se identifica la motivación | G160: =IF(E160="","",VLOOKUP(E160,Causas!$A$2:$D$90,3,FALSE())) -> 2.1 | H160: =IF(E160="","",VLOOKUP(E160,Causas!$A$2:$D$90,4,FALSE())) -> Incendios intencionales | I160: =IF(E160="","",VLOOKUP(E160,Causas!$A$2:$E$90,5,FALSE())) -> Intencionales | J160: 248874 | K160: 6002322 | L160: 0.3 | M160: Marzo | N160: ITA_N-159_R20-BAJOS DE COPIHUE_NR-289 | O160: Linares | P160: 46019 | Q160: =MONTH(P160) -> 12
...

Sheet Causas
A1: Código especifico | B1: Causa | C1: Código general | D1: Causa general | E1: Grupo de causa
A2: 1.1.1 | B2: Quema avisada de desechos forestales que se propaga libre y sin control | C2: 1.1 | D2: Faenas forestales | E2: Accidentales
A3: 1.1.2 | B3: Partículas incandescentes generadas por roce de maquinaria o herramienta forestal con rocas, cercos o material metálico | C3: 1.1 | D3: Faenas forestales | E3: Accidentales
A4: 1.1.3 | B4: Otros incendios accidentales no clasificados en faenas forestales | C4: 1.1 | D4: Faenas forestales | E4: Accidentales
A5: 1.2.1 | B5: Quema avisada de desechos agrícolas que se propaga libre y sin control | C5: 1.2 | D5: Faenas agrícolas y pecuarias | E5: Accidentales
A6: 1.2.2 | B6: Partículas incandescentes generadas por roce de maquinaria o herramienta agrícola con rocas, cercos o material metálico | C6: 1.2 | D6: Faenas agrícolas y pecuarias | E6: Accidentales
A7: 1.2.3 | B7: Otros incendios accidentales no clasificados en faenas agropecuarias | C7: 1.2 | D7: Faenas agrícolas y pecuarias | E7: Accidentales
A8: 1.3.1 | B8: Empleo de fuentes de calor en áreas habilitadas, como fogatas, cocinillas u otro elemento para cocinar, calefacción, iluminación u otros fines | C8: 1.3 | D8: Actividades al aire libre (camping, excursiones, caza, pesca, otros) | E8: Accidentales
A9: 1.4.1 | B9: Accidente ferroviario | C9: 1.4 | D9: Vías férreas | E9: Accidentales
A10: 1.4.2 | B10: Partículas incandescentes generadas por el paso del ferrocarril (con mantención de fajas de seguridad) | C10: 1.4 | D10: Vías férreas | E10: Accidentales
A11: 1.5.1 | B11: Caída de avión, helicóptero u otras aeronaves, en operaciones de combate de incendios forestales o reconocimientos de zonas | C11: 1.5 | D11: Actividades de control y extinción de incendios forestales | E11: Accidentales
A12: 1.6.1 | B12: Incendio estructural | C12: 1.6 | D12: Parcelaciones, edificaciones residenciales, industriales u otras en zonas rurales o de interfaz | E12: Accidentales
... A90: 5.1.2 | B90: La causa no es investigada | C90: 5.1 | D90: Incendios de causa indeterminada | E90: Indeterminadas

Sheet DATOS4
A1: ID | B1: Temporada | C1: Comuna | D1: N° regional Incendio | E1: Nombre incendio | F1: Código causa Investigada | G1: Nombre causa específica | H1: Codigo causa general | I1: Causa General | J1: Grupo de causas | K1: Mes investigación | L1: Nombre informe | M1: Provincia | N1: Coordenada X | O1: Coordenada Y
A2: ='Invest. IF'!A2 -> 1 | B2: ='Invest. IF'!#REF! -> #REF! | C2: ='Invest. IF'!B2 -> San Clemente | D2: ='Invest. IF'!C2 -> 5 | E2: ='Invest. IF'!D2 -> Flor del Llano | F2: ='Invest. IF'!E2 -> 4.8.1 | G2: ='Invest. IF'!F2 -> Quema no avisada con fines de limpieza en canales, cunetas, cercos o caminos (en predios particulares o públicos) que se propaga libre y sin control | H2: ='Invest. IF'!G2 -> 4.8 | I2: ='Invest. IF'!H2 -> Otras quemas | J2: ='Invest. IF'!I2 -> Negligentes | K2: ='Invest. IF'!M2 -> Septiembre | L2: ='Invest. IF'!N2 -> ITA_N-1_R20-FLOR DEL LLANO_NR-5 | M2: ='Invest. IF'!O2 -> Talca | N2: ='Invest. IF'!J2 -> 269761 | O2: ='Invest. IF'!K2 -> 6068526
A3: ='Invest. IF'!A3 -> 2 | B3: ='Invest. IF'!#REF! -> #REF! | C3: ='Invest. IF'!B3 -> Pelluhue | D3: ='Invest. IF'!C3 -> 6 | E3: ='Invest. IF'!D3 -> Canelillos | F3: ='Invest. IF'!E3 -> 4.1.1 | G3: ='Invest. IF'!F3 -> Quema no avisada de desechos forestales que se propaga libre y sin control | H3: ='Invest. IF'!G3 -> 4.1 | I3: ='Invest. IF'!H3 -> Faenas forestales | J3: ='Invest. IF'!I3 -> Negligentes | K3: ='Invest. IF'!M3 -> Septiembre | L3: ='Invest. IF'!N3 -> ITA_N-2_R20-CANELILLOS_NR-6 | M3: ='Invest. IF'!O3 -> Cauquenes | N3: ='Invest. IF'!J3 -> 710893 | O3: ='Invest. IF'!K3 -> 6015439
A4: ='Invest. IF'!A4 -> 3 | B4: ='Invest. IF'!#REF! -> #REF! | C4: ='Invest. IF'!B4 -> Parral | D4: ='Invest. IF'!C4 -> 7 | E4: ='Invest. IF'!D4 -> San Pablo | F4: ='Invest. IF'!E4 -> 4.2.1 | G4: ='Invest. IF'!F4 -> Quema no avisada de desechos agrícolas que se propaga libre y sin control | H4: ='Invest. IF'!G4 -> 4.2 | I4: ='Invest. IF'!H4 -> Faenas agrícolas y pecuarias | J4: ='Invest. IF'!I4 -> Negligentes | K4: ='Invest. IF'!M4 -> Septiembre | L4: ='Invest. IF'!N4 -> ITA_N-3_R20-SAN PABLO_NR-7 | M4: ='Invest. IF'!O4 -> Linares | N4: ='Invest. IF'!J4 -> 248592 | O4: ='Invest. IF'!K4 -> 5994895
A5: ='Invest. IF'!A5 -> 4 | B5: ='Invest. IF'!#REF! -> #REF! | C5: ='Invest. IF'!B5 -> Pencahue | D5: ='Invest. IF'!C5 -> 9 | E5: ='Invest. IF'!D5 -> Santa Patricia | F5: ='Invest. IF'!E5 -> 4.6.5 | G5: ='Invest. IF'!F5 -> Empleo de fuentes de calor en actividades relacionadas a parcelaciones (asados, tijerales, fogatas, otros) | H5: ='Invest. IF'!G5 -> 4.6 | I5: ='Invest. IF'!H5 -> Parcelaciones, edificaciones residenciales, industriales u otras en zonas rurales o de interfaz | J5: ='Invest. IF'!I5 -> Negligentes | K5: ='Invest. IF'!M5 -> Octubre | L5: ='Invest. IF'!N5 -> ITA_N-4_R20-SANTA PATRICIA_NR-9 | M5: ='Invest. IF'!O5 -> Talca | N5: ='Invest. IF'!J5 -> 255515 | O5: ='Invest. IF'!K5 -> 6084357
A6: ='Invest. IF'!A6 -> 5 | B6: ='Invest. IF'!#REF! -> #REF! | C6: ='Invest. IF'!B6 -> Talca | D6: ='Invest. IF'!C6 -> 11 | E6: ='Invest. IF'!D6 -> Palmira | F6: ='Invest. IF'!E6 -> 4.8.1 | G6: ='Invest. IF'!F6 -> Quema no avisada con fines de limpieza en canales, cunetas, cercos o caminos (en predios particulares o públicos) que se propaga libre y sin control | H6: ='Invest. IF'!G6 -> 4.8 | I6: ='Invest. IF'!H6 -> Otras quemas | J6: ='Invest. IF'!I6 -> Negligentes | K6: ='Invest. IF'!M6 -> Octubre | L6: ='Invest. IF'!N6 -> ITA_N-5_R20-PALMIRA_NR-11 | M6: ='Invest. IF'!O6 -> Talca | N6: ='Invest. IF'!J6 -> 261374 | O6: ='Invest. IF'!K6 -> 6072852
A7: ='Invest. IF'!A7 -> 6 | B7: ='Invest. IF'!#REF! -> #REF! | C7: ='Invest. IF'!B7 -> Teno | D7: ='Invest. IF'!C7 -> 14 | E7: ='Invest. IF'!D7 -> Rincón de San Carlos | F7: ='Invest. IF'!E7 -> 4.2.8 | G7: ='Invest. IF'!F7 -> Otras causas negligentes no clasificadas en faenas agrícolas y pecuarias | H7: ='Invest. IF'!G7 -> 4.2 | I7: ='Invest. IF'!H7 -> Faenas agrícolas y pecuarias | J7: ='Invest. IF'!I7 -> Negligentes | K7: ='Invest. IF'!M7 -> Octubre | L7: ='Invest. IF'!N7 -> ITA_N-6_R20-RINCON DE SAN CARLOS_NR-14 | M7: ='Invest. IF'!O7 -> Curicó | N7: ='Invest. IF'!J7 -> 317177 | O7: ='Invest. IF'!K7 -> 6137223
A8: ='Invest. IF'!A8 -> 7 | B8: ='Invest. IF'!#REF! -> #REF! | C8: ='Invest. IF'!B8 -> Sagrada Familia | D8: ='Invest. IF'!C8 -> 19 | E8: ='Invest. IF'!D8 -> La Isla | F8: ='Invest. IF'!E8 -> 4.2.1 | G8: ='Invest. IF'!F8 -> Quema no avisada de desechos agrícolas que se propaga libre y sin control | H8: ='Invest. IF'!G8 -> 4.2 | I8: ='Invest. IF'!H8 -> Faenas agrícolas y pecuarias | J8: ='Invest. IF'!I8 -> Negligentes | K8: ='Invest. IF'!M8 -> Octubre | L8: ='Invest. IF'!N8 -> ITA_N-7_R20-LA ISLA_NR-19 | M8: ='Invest. IF'!O8 -> Curicó | N8: ='Invest. IF'!J8 -> 258197 | O8: ='Invest. IF'!K8 -> 6111756
A9: ='Invest. IF'!A9 -> 8 | B9: ='Invest. IF'!#REF! -> #REF! | C9: ='Invest. IF'!B9 -> Sagrada Familia | D9: ='Invest. IF'!C9 -> 20 | E9: ='Invest. IF'!D9 -> Huaquen | F9: ='Invest. IF'!E9 -> 4.8.4 | G9: ='Invest. IF'!F9 -> Empleo de fuentes de calor para eliminación de fauna (roedores, reptiles, avispas, otros) | H9: ='Invest. IF'!G9 -> 4.8 | I9: ='Invest. IF'!H9 -> Otras quemas | J9: ='Invest. IF'!I9 -> Negligentes | K9: ='Invest. IF'!M9 -> Octubre | L9: ='Invest. IF'!N9 -> ITA_N-8_R20-HUAQUEN_NR-20 | M9: ='Invest. IF'!O9 -> Curicó | N9: ='Invest. IF'!J9 -> 256366 | O9: ='Invest. IF'!K9 -> 6111056
A10: ='Invest. IF'!A10 -> 9 | B10: ='Invest. IF'!#REF! -> #REF! | C10: ='Invest. IF'!B10 -> Cauquenes | D10: ='Invest. IF'!C10 -> 23 | E10: ='Invest. IF'!D10 -> Tabolguen | F10: ='Invest. IF'!E10 -> 2.1.1 | G10: ='Invest. IF'!F10 -> Provocado, no se identifica la motivación | H10: ='Invest. IF'!G10 -> 2.1 | I10: ='Invest. IF'!H10 -> Incendios intencionales | J10: ='Invest. IF'!I10 -> Intencionales | K10: ='Invest. IF'!M10 -> Octubre | L10: ='Invest. IF'!N10 -> ITA_N-9_R20-TABOLGUEN_NR-23 | M10: ='Invest. IF'!O10 -> Cauquenes | N10: ='Invest. IF'!J10 -> 736662 | O10: ='Invest. IF'!K10 -> 6022384
A11: ='Invest. IF'!A11 -> 10 | B11: ='Invest. IF'!#REF! -> #REF! | C11: ='Invest. IF'!B11 -> Pelluhue | D11: ='Invest. IF'!C11 -> 21 | E11: ='Invest. IF'!D11 -> Chovellen | F11: ='Invest. IF'!E11 -> 4.10.12 | G11: ='Invest. IF'!F11 -> Otras actividades negligentes no clasificadas | H11: ='Invest. IF'!G11 -> 4.10 | I11: ='Invest. IF'!H11 -> Otras causas | J11: ='Invest. IF'!I11 -> Negligentes | K11: ='Invest. IF'!M11 -> Octubre | L11: ='Invest. IF'!N11 -> ITA_N-10_R20-CHOVELLEN_NR-21 | M11: ='Invest. IF'!O11 -> Cauquenes | N11: ='Invest. IF'!J11 -> 711105 | O11: ='Invest. IF'!K11 -> 6024701
A12: ='Invest. IF'!A12 -> 11 | B12: ='Invest. IF'!#REF! -> #REF! | C12: ='Invest. IF'!B12 -> Yerbas Buenas | D12: ='Invest. IF'!C12 -> 33 | E12: ='Invest. IF'!D12 -> Coironal | F12: ='Invest. IF'!E12 -> 4.2.6 | G12: ='Invest. IF'!F12 -> Quema avisada de desechos agrícolas mal ejecutada que se propaga libre y sin control (según plan de quema y/o aviso de quemas) | H12: ='Invest. IF'!G12 -> 4.2 | I12: ='Invest. IF'!H12 -> Faenas agrícolas y pecuarias | J12: ='Invest. IF'!I12 -> Negligentes | K12: ='Invest. IF'!M12 -> Octubre | L12: ='Invest. IF'!N12 -> ITA_N-11_R20-COIRONAL_NR-33 | M12: ='Invest. IF'!O12 -> Linares | N12: ='Invest. IF'!J12 -> 260770 | O12: ='Invest. IF'!K12 -> 6038159
A13: ='Invest. IF'!A13 -> 12 | B13: ='Invest. IF'!#REF! -> #REF! | C13: ='Invest. IF'!B13 -> Longaví | D13: ='Invest. IF'!C13 -> 37 | E13: ='Invest. IF'!D13 -> Camino a la quinta | F13: ='Invest. IF'!E13 -> 4.2.8 | G13: ='Invest. IF'!F13 -> Otras causas negligentes no clasificadas en faenas agrícolas y pecuarias | H13: ='Invest. IF'!G13 -> 4.2 | I13: ='Invest. IF'!H13 -> Faenas agrícolas y pecuarias | J13: ='Invest. IF'!I13 -> Negligentes | K13: ='Invest. IF'!M13 -> Octubre | L13: ='Invest. IF'!N13 -> ITA_N-12_R20-CAMINO A LA QUINTA_NR-37 | M13: ='Invest. IF'!O13 -> Linares | N13: ='Invest. IF'!J13 -> 259646 | O13: ='Invest. IF'!K13 -> 6003027
... A386: ='Invest. IF'!A386 -> 385 | B386: ='Invest. IF'!#REF! -> #REF! | C386: ='Invest. IF'!B386 -> Río Claro | D386: ='Invest. IF'!C386 -> 315 | E386: ='Invest. IF'!D386 -> Itahue 3 | F386: ='Invest. IF'!E386 -> 4.8.1 | G386: ='Invest. IF'!F386 -> Quema no avisada con fines de limpieza en canales, cunetas, cercos o caminos (en predios particulares o públicos) que se propaga libre y sin control | H386: ='Invest. IF'!G386 -> 4.8 | I386: ='Invest. IF'!H386 -> Otras quemas | J386: ='Invest. IF'!I386 -> Negligentes | K386: ='Invest. IF'!M386 -> Junio | L386: ='Invest. IF'!N386 -> ITA_N-385_R20-ITAHUE 3_NR-315 | M386: ='Invest. IF'!O386 -> Talca | N386: ='Invest. IF'!J386 -> 285083 | O386: ='Invest. IF'!K386 -> 6107393
